<?xml version="1.0"?>
<robot name="robot" xmlns:xacro="http://ros.org/wiki/xacro">
  <xacro:include filename="$(find rbe502_sim)/urdf/robot.gazebo.xacro"/>

  <material name="blue">
    <color rgba="0 0 1 1"/>
  </material>

  <link name="base_footprint"/>

  <link name="base_link">
    <visual>
      <geometry>
        <mesh filename="package://rbe502_sim/meshes/RobotBody.stl" scale="0.001 0.001 0.001"/>
      </geometry>
      <origin rpy="${pi/2} 0 0"/>
    </visual>
    <inertial>
      <mass value="1.51518"/>
      <inertia ixx="2.286e-2" ixy="-2799.989e-9" ixz="-1384.644e-9" iyy="3.069e-3" iyz="-1.063e-3" izz="2.054e-2"/>
      <origin rpy="${pi/2} 0 0"/>

    </inertial>
    <collision>
      <geometry>
       <mesh filename="package://rbe502_sim/meshes/RobotBody.stl" scale="0.001 0.001 0.001"/>
        <!-- <box size=".05 .035 .30"/> -->
      </geometry>
      
      <!-- <origin xyz="0 0 .15" rpy="0 0 0"/> -->
      <origin rpy="${pi/2} 0 0"/>
    </collision>
  </link> -->

  <joint name="footprint_to_base_link" type="fixed">
    <parent link="base_footprint"/>
    <child link="base_link"/>
  </joint>


  <link name="left_wheel">
    <visual>
      <geometry>
        <mesh filename="package://rbe502_sim/meshes/BalanceRobot/Wheel.stl" scale="0.001 0.001 0.001"/>
      </geometry>
      <origin xyz="0 0 0" rpy="${pi/2} 0 0"/>
      <material name="blue"/>
    </visual>
    <inertial>
      <mass value="0.053337"/>
      <inertia ixx="1.988e-2" ixy=" -1657.286e-9" ixz="-6297.698e-9" iyy="4.177e-3" iyz="2.292e-3" izz="1.645e-2"/>
      <origin xyz="0 0 0" rpy="${pi/2} 0 0"/>
    </inertial>
    <collision>
      <geometry>
       <mesh filename="package://rbe502_sim/meshes/BalanceRobot/Wheel.stl" scale="0.001 0.001 0.001"/>
       <!-- <box size=".05 .035 .30"/> -->
      </geometry>
      <origin xyz="0 0 0" rpy="${pi/2} 0 0"/>
    </collision>
  </link>

  <joint name="base_link_to_left_wheel" type="continuous">
    <parent link="base_link"/>
    <child link="left_wheel"/>
    <axis xyz="0 1 0"/>
    <origin xyz="0 -0.081 0"/>
  </joint>

  <link name="right_wheel">
    <visual>
      <geometry>
        <mesh filename="package://rbe502_sim/meshes/BalanceRobot/Wheel.stl" scale="0.001 0.001 0.001"/>
      </geometry>
      <origin xyz="0 0 0" rpy="${pi/2} 0 ${pi}"/>
    </visual>
    <inertial>
      <mass value="0.053337"/>
      <inertia ixx="1.988e-2" ixy=" -1657.286e-9" ixz="-6297.698e-9" iyy="4.177e-3" iyz="2.292e-3" izz="1.645e-2"/>
      <origin xyz="0 0 0" rpy="${pi/2} 0 ${pi}"/>

    </inertial>
    <collision>
      <geometry>
        <mesh filename="package://rbe502_sim/meshes/BalanceRobot/Wheel.stl" scale="0.001 0.001 0.001"/>
      </geometry>
      <origin xyz="0 0 0" rpy="${pi/2} 0 ${pi}"/>
    </collision>
  </link>

  <joint name="base_link_to_right_wheel" type="continuous">
    <parent link="base_link"/>
    <child link="right_wheel"/>
    <axis xyz="0 1 0"/>
    <origin xyz="0 0.055 0" rpy="0 0 0"/>
  </joint>
  
<link name="imu_link"/>

<joint name="imu_linked" type="fixed">
  <parent link="base_link"/>
  <child link="imu_link"/>
  <origin xyz="0 0 .1475 "/>
</joint>

  
</robot>

